//falso positivo
test('Não deveria passar!', () => {
  setTimeout(() => {
    expect(10).toBe(5);
    console.log('Deveria falhar!');
  }, 500);
});

//tentando corrigir, mas sem tratar erro dá timeout
test('Não deveria passar!', (done) => {
  setTimeout(() => {
    expect(10).toBe(5);
    console.log('Deveria falhar!');
    done();
  }, 500);
});

//usamos try/catch, mas ainda sem tratar o erro dá falso positivo
test('Não deveria passar!', (done) => {
  setTimeout(() => {
    try {
      expect(10).toBe(5);
      console.log('Deveria falhar!');
      done();
    } catch (error) {
      done();
    }
  }, 500);
});

//agora, com try/catch, tratando o erro, executa corretamente o teste
test('Não deveria passar!', (done) => {
  setTimeout(() => {
    try {
      expect(10).toBe(5);
      console.log('Deveria falhar!');
      done();
    } catch (error) {
      done(error); // Alteramos esta linha
    }
  }, 500);
});

//outro teste
const asyncSum = (a, b, callback) => {
  setTimeout(() => {
    const result = a + b;
    callback(result);
  }, 500);
};

test('Testando asyncSum, soma 5 mais 10', (done) => {
  asyncSum(5, 10, (result) => {
    try {
      expect(result).toBe(15);
      done();
    } catch (error) {
      done(error);
    }
  });
});